Workbook

Sheet Clientes
A1: Cuit | B1: Razon Social | C1: País | D1: Rubro | E1: Dirección fiscal | F1: Localidad | G1: Provincia | H1: Condición Iva | I1: Notas
A2: 30-52999439-3 | B2: 3M Obsoleto | C2: Argentina | E2: Los Árboles 842 | F2: Hurlingham
A3: 30-50084630-1 | B3: Abbott Laboratories Argentina SA | C3: Argentina | E3: Ing. Butti 240 | F3: CABA
A4: 30-50012088-2 | B4: ASOCIACIÓN DE COOP. ARG. COOP. LTDA. | C4: Argentina | E4: Calle 4 y Ruta Provincial S/N | F4: campana
A5: 30-50287435-3 | B5: Aceitera General Deheza SA | C5: Argentina | E5: Int. Adrian Urquiza 149 | F5: General Deheza
A6: 30-65517437-7 | B6: Acon SCC | C6: Argentina | E6: Av. Lisandro de la torre 949 | F6: Río Gallegos
A7: 30-65397646-8 | B7: Adm. Nac. De alic, medic y Tecnologia medica (ANMAT) | C7: Argentina | E7: Av. De mayo 869 | F7: CABA
A8: 30-64469661-4 | B8: Administración Agua Provincial del Chaco | C8: Argentina | E8: Ruta N. Avellaneda KM 12,5 resistencia S/N | F8: Resistencia
A9: 30-66314099-6 | B9: ANMAT (Inal) | C9: Argentina | E9: Av Caseros 2161 | F9: CABA
A10: 30-68521819-9 | B10: A-Evangelista S.A (AESA) | C10: Argentina | E10: Barreiro 2871 | F10: Ezeiza
A11: 30-50139538-9 | B11: Aga S.A. | C11: Argentina | E11: Calle 9 y 19-Ruta 8 Km. 60 N/A | F11: Parque Industrial Pilar
A12: 34-99903208-9 | B12: AGC (Agencia Gubernamental de Control) | C12: Argentina | E12: Calle Tte. Gral. Juan Domingo Perón 2933 | F12: CABA
A13: 30-68168182-1 | B13: Agro Natural | C13: Argentina | E13: Ruta 14 s/n - Km 20 N/A | F13: Ullum
... A739: 20-22110032-9 | B739: Ariel. J. Grillo | C739: Argentina | E739: Colombia 914 | F739: Bahía Blanca

Sheet Establecimientos
A1: Cuit Cliente | B1: Nombre | C1: Dirección | D1: Localidad | E1: Provicia | F1: Codigo postal | G1: Tipo | H1: Latitud | I1: Longitud
A2: 30-52999439-3 | B2: =+D2 -> Hurlingham | C2: Los Árboles 842 | D2: Hurlingham
A3: 30-50084630-1 | B3: =+D3 -> CABA | C3: Ing. Butti 240 | D3: CABA
A4: 30-50012088-2 | B4: =+D4 -> campana | C4: Calle 4 y Ruta Provincial S/N | D4: campana
A5: 30-50287435-3 | B5: =+D5 -> General Deheza | C5: Int. Adrian Urquiza 149 | D5: General Deheza
A6: 30-65517437-7 | B6: =+D6 -> Río Gallegos | C6: Av. Lisandro de la torre 949 | D6: Río Gallegos
A7: 30-65397646-8 | B7: =+D7 -> CABA | C7: Av. De mayo 869 | D7: CABA
A8: 30-64469661-4 | B8: =+D8 -> Resistencia | C8: Ruta N. Avellaneda KM 12,5 resistencia S/N | D8: Resistencia
A9: 30-66314099-6 | B9: =+D9 -> CABA | C9: Av Caseros 2161 | D9: CABA
A10: 30-68521819-9 | B10: =+D10 -> Ezeiza | C10: Barreiro 2871 | D10: Ezeiza
A11: 30-50139538-9 | B11: =+D11 -> Parque Industrial Pilar | C11: Calle 9 y 19-Ruta 8 Km. 60 N/A | D11: Parque Industrial Pilar
A12: 34-99903208-9 | B12: =+D12 -> CABA | C12: Calle Tte. Gral. Juan Domingo Perón 2933 | D12: CABA
A13: 30-68168182-1 | B13: =+D13 -> Ullum | C13: Ruta 14 s/n - Km 20 N/A | D13: Ullum
... A739: 00-00000000-0 | B739: =+D739 -> Bahía Blanca | C739: Colombia 914 | D739: Bahía Blanca

Sheet Sistemas
A1: Cuit cliente | B1: Nombre Cliente | C1: Establecimiento | D1: Categoria ID | E1: Nombre sistema | F1: Codigo interno | G1: Software | H1: Observaciones
A2: =_xlfn.XLOOKUP(B2,Clientes!B:B,Clientes!A:A,"") -> 30-52999439-3 | B2: 3M Obsoleto | C2: =_xlfn.XLOOKUP(A2,Establecimientos!A:A,Establecimientos!B:B,"") -> Hurlingham | E2: HPLC 1100 | F2: HPLC 1
A3: =_xlfn.XLOOKUP(B3,Clientes!B:B,Clientes!A:A,"") -> 30-52999439-3 | B3: 3M Obsoleto | C3: =_xlfn.XLOOKUP(A3,Establecimientos!A:A,Establecimientos!B:B,"") -> Hurlingham | E3: HPLC 1100 | F3: HPLC 2
A4: =_xlfn.XLOOKUP(B4,Clientes!B:B,Clientes!A:A,"") -> 30-50084630-1 | B4: Abbott Laboratories Argentina SA | C4: =_xlfn.XLOOKUP(A4,Establecimientos!A:A,Establecimientos!B:B,"") -> CABA | E4: HPLC 1050 | F4: CC-066
A5: =_xlfn.XLOOKUP(B5,Clientes!B:B,Clientes!A:A,"") -> 30-50084630-1 | B5: Abbott Laboratories Argentina SA | C5: =_xlfn.XLOOKUP(A5,Establecimientos!A:A,Establecimientos!B:B,"") -> CABA | E5: HPLC 1100 | F5: DS-015
A6: =_xlfn.XLOOKUP(B6,Clientes!B:B,Clientes!A:A,"") -> 30-50084630-1 | B6: Abbott Laboratories Argentina SA | C6: =_xlfn.XLOOKUP(A6,Establecimientos!A:A,Establecimientos!B:B,"") -> CABA | E6: HPLC 1100 | F6: DS-05
A7: =_xlfn.XLOOKUP(B7,Clientes!B:B,Clientes!A:A,"") -> 30-50084630-1 | B7: Abbott Laboratories Argentina SA | C7: =_xlfn.XLOOKUP(A7,Establecimientos!A:A,Establecimientos!B:B,"") -> CABA | E7: HPLC 1260 | F7: DS-041
A8: =_xlfn.XLOOKUP(B8,Clientes!B:B,Clientes!A:A,"") -> 30-50084630-1 | B8: Abbott Laboratories Argentina SA | C8: =_xlfn.XLOOKUP(A8,Establecimientos!A:A,Establecimientos!B:B,"") -> CABA | E8: HPLC 1260 | F8: ISTAQL-040
A9: =_xlfn.XLOOKUP(B9,Clientes!B:B,Clientes!A:A,"") -> 30-50012088-2 | B9: ASOCIACIÓN DE COOP. ARG. COOP. LTDA. | C9: =_xlfn.XLOOKUP(A9,Establecimientos!A:A,Establecimientos!B:B,"") -> campana | E9: Density meter with oscillating U-tube | F9: CCA-LB01-DA03
A10: =_xlfn.XLOOKUP(B10,Clientes!B:B,Clientes!A:A,"") -> 30-50012088-2 | B10: ASOCIACIÓN DE COOP. ARG. COOP. LTDA. | C10: =_xlfn.XLOOKUP(A10,Establecimientos!A:A,Establecimientos!B:B,"") -> campana | E10: GC 6890 | F10: GC-03
A11: =_xlfn.XLOOKUP(B11,Clientes!B:B,Clientes!A:A,"") -> 30-50012088-2 | B11: ASOCIACIÓN DE COOP. ARG. COOP. LTDA. | C11: =_xlfn.XLOOKUP(A11,Establecimientos!A:A,Establecimientos!B:B,"") -> campana | E11: GC 7890 | F11: GC-02
A12: =_xlfn.XLOOKUP(B12,Clientes!B:B,Clientes!A:A,"") -> 30-50012088-2 | B12: ASOCIACIÓN DE COOP. ARG. COOP. LTDA. | C12: =_xlfn.XLOOKUP(A12,Establecimientos!A:A,Establecimientos!B:B,"") -> campana | E12: GC MSD 6890 | F12: MS-01
A13: =_xlfn.XLOOKUP(B13,Clientes!B:B,Clientes!A:A,"") -> 30-50012088-2 | B13: ASOCIACIÓN DE COOP. ARG. COOP. LTDA. | C13: =_xlfn.XLOOKUP(A13,Establecimientos!A:A,Establecimientos!B:B,"") -> campana | E13: HPLC 1100 | F13: CCA-LB01-LC-01
... A923: =_xlfn.XLOOKUP(B923,Clientes!B:B,Clientes!A:A,"") -> 30-71608764-2 | B923: TASQA SAU | C923: =_xlfn.XLOOKUP(A923,Establecimientos!A:A,Establecimientos!B:B,"") -> Ingeniero Allan | E923: GC 7890 | F923: G3440B

Sheet Modulos
A1: Cuit Cliente | B1: Establecimiento | C1: Codigo sistema | D1: Nombre modulo | E1: Descripción | F1: Número de serie | G1: Firmware | H1: Marca | I1: Observaciones
A2: 30-53918765-8 | C2: D-14163 | D2: 816 | E2: =IFERROR(VLOOKUP(D2,'Resumen Módulos'!$A$2:$B$324,3,FALSE),"") | F2: 00153/53247 | H2: Agilent
A3: 33-53487696-9 | C3: CC24/CC25 | D3: 5975 | E3: =IFERROR(VLOOKUP(D3,'Resumen Módulos'!$A$2:$B$324,3,FALSE),"") | F3: US74828045 | H3: Agilent
A4: 30-52995208-9 | C4: GC 7820 N°1 | D4: 5975 | E4: =IFERROR(VLOOKUP(D4,'Resumen Módulos'!$A$2:$B$324,3,FALSE),"") | F4: US11031604 | H4: Agilent
A5: 30-70938711-8 | C5: GC 6890 | D5: 7683 | E5: =IFERROR(VLOOKUP(D5,'Resumen Módulos'!$A$2:$B$324,3,FALSE),"") | H5: Agilent
A6: 30-58301360-8 | C6: QB-110 | D6: 7694 | E6: =IFERROR(VLOOKUP(D6,'Resumen Módulos'!$A$2:$B$324,3,FALSE),"") | F6: IT7090792 | H6: Agilent
A7: 30-50795084-8 | C7: GC 7890 | D7: 7697 | E7: =IFERROR(VLOOKUP(D7,'Resumen Módulos'!$A$2:$B$324,3,FALSE),"") | F7: CN13140002 | H7: Agilent
A8: 30-50152188-0 | C8: UV 8452 | D8: 8452 | E8: =IFERROR(VLOOKUP(D8,'Resumen Módulos'!$A$2:$B$324,3,FALSE),"") | F8: 3104G01987 | H8: Agilent
A9: 30-70956507-5 | C9: ORG-E-004 | D9: µECD | E9: =IFERROR(VLOOKUP(D9,'Resumen Módulos'!$A$2:$B$324,3,FALSE),"") | F9: US00002324 | H9: Agilent
A10: 30-70956507-5 | C10: ORG-E-052 | D10: µECD | E10: =IFERROR(VLOOKUP(D10,'Resumen Módulos'!$A$2:$B$324,3,FALSE),"") | F10: US10821030 | H10: Agilent
A11: 30-60757294-8 | C11: GC 6890 N°2 | D11: µECD | E11: =IFERROR(VLOOKUP(D11,'Resumen Módulos'!$A$2:$B$324,3,FALSE),"") | F11: US10641050 | H11: Agilent
A12: 30-58676219-9 | C12: GC-02 | D12: µECD | E12: =IFERROR(VLOOKUP(D12,'Resumen Módulos'!$A$2:$B$324,3,FALSE),"") | F12: US10606041 | H12: Agilent
A13: 30-70836345-2 | C13: GC 7890 N°1 | D13: µECD | E13: =IFERROR(VLOOKUP(D13,'Resumen Módulos'!$A$2:$B$324,3,FALSE),"") | F13: CN11111135 | H13: Agilent
A14: 30-70123382-0 | C14: LAB14 | D14: µECD | E14: =IFERROR(VLOOKUP(D14,'Resumen Módulos'!$A$2:$B$324,3,FALSE),"") | F14: US10515014 | H14: Agilent
A15: 30-67630365-7 | C15: GC 7890 | D15: µECD | E15: =IFERROR(VLOOKUP(D15,'Resumen Módulos'!$A$2:$B$324,3,FALSE),"") | H15: Agilent
A16: 30-70791990-2 | C16: 129414 | D16: µECD | E16: =IFERROR(VLOOKUP(D16,'Resumen Módulos'!$A$2:$B$324,3,FALSE),"") | F16: US16033035 | H16: Agilent
A17: 33-50170702-9 | C17: A0098 | D17: 0001-6354 | E17: =IFERROR(VLOOKUP(D17,'Resumen Módulos'!$A$2:$B$324,3,FALSE),"") | F17: 1001621 | H17: Agilent
A18: 30-65199570-8 | C18: ICC 33 | D18: 0001-6354 | E18: =IFERROR(VLOOKUP(D18,'Resumen Módulos'!$A$2:$B$324,3,FALSE),"") | F18: 1001486 | H18: Agilent
A19: 30-57730987-2 | C19: HPLC 3 | D19: 0001-6354 | E19: =IFERROR(VLOOKUP(D19,'Resumen Módulos'!$A$2:$B$324,3,FALSE),"") | F19: 1001620 | H19: Agilent
A20: 30-50140709-3 | C20: QC-019 | D20: 0001-6501 | E20: =IFERROR(VLOOKUP(D20,'Resumen Módulos'!$A$2:$B$324,3,FALSE),"") | F20: 1000003 | H20: Agilent
A21: 30-58676189-3 | C21: HPLC 1100 | D21: 1046A | E21: =IFERROR(VLOOKUP(D21,'Resumen Módulos'!$A$2:$B$324,3,FALSE),"") | H21: Agilent
A22: 30-71474645-2 | C22: HPLC-01 | D22: 1046A | E22: =IFERROR(VLOOKUP(D22,'Resumen Módulos'!$A$2:$B$324,3,FALSE),"") | H22: Agilent
A23: 30-70927554-9 | C23: GC7890 | D23: 18594A | E23: =IFERROR(VLOOKUP(D23,'Resumen Módulos'!$A$2:$B$324,3,FALSE),"") | H23: Agilent
A24: 30-71134016-1 | C24: GC 5890 | D24: 18594B | E24: =IFERROR(VLOOKUP(D24,'Resumen Módulos'!$A$2:$B$324,3,FALSE),"") | F24: 3439A36734 | H24: Agilent
A25: 30-71411917-2 | C25: GC 5890 | D25: 18596B | E25: =IFERROR(VLOOKUP(D25,'Resumen Módulos'!$A$2:$B$324,3,FALSE),"") | F25: 3304A31144 | G25: N/A | H25: Agilent
A26: 33-53487696-9 | C26: CC10 | D26: 18596C | E26: =IFERROR(VLOOKUP(D26,'Resumen Módulos'!$A$2:$B$324,3,FALSE),"") | F26: US74703025 | H26: Agilent
A27: 30-50350872-5 | C27: Equipo GC 1 | D27: 18596C | E27: =IFERROR(VLOOKUP(D27,'Resumen Módulos'!$A$2:$B$324,3,FALSE),"") | F27: 3603A041026 | H27: Agilent
A28: 30-68307613-5 | C28: CGA-01 | D28: 18596C | E28: =IFERROR(VLOOKUP(D28,'Resumen Módulos'!$A$2:$B$324,3,FALSE),"") | F28: 3626A42363 | H28: Agilent
A29: 30-50374753-3 | C29: SAP3392 | D29: 18596C | E29: =IFERROR(VLOOKUP(D29,'Resumen Módulos'!$A$2:$B$324,3,FALSE),"") | F29: US84404966 | H29: Agilent
A30: 30-59272454-1 | C30: GC 701 | D30: 18596C | E30: =IFERROR(VLOOKUP(D30,'Resumen Módulos'!$A$2:$B$324,3,FALSE),"") | F30: US83204596 | H30: Agilent
A31: 30-59272454-1 | C31: GC 703 | D31: 18596C | E31: =IFERROR(VLOOKUP(D31,'Resumen Módulos'!$A$2:$B$324,3,FALSE),"") | F31: 3424A42229 | H31: Agilent
A32: 30-57076089-7 | C32: ECC-011 | D32: 35900E | E32: =IFERROR(VLOOKUP(D32,'Resumen Módulos'!$A$2:$B$324,3,FALSE),"") | F32: CN00002649 | G32: A.05.11 | H32: Agilent
A33: 30-71097036-6 | C33: CTC2 | D33: 45-EP | E33: =IFERROR(VLOOKUP(D33,'Resumen Módulos'!$A$2:$B$324,3,FALSE),"") | F33: 376258 | H33: Agilent
A34: 30-56168969-1 | C34: GC 5890 N°2 | D34: 5890A GC | E34: =IFERROR(VLOOKUP(D34,'Resumen Módulos'!$A$2:$B$324,3,FALSE),"") | F34: 2750A16128 | H34: Agilent
A35: 30-71134016-1 | C35: GC 5890 | D35: 5972S | E35: =IFERROR(VLOOKUP(D35,'Resumen Módulos'!$A$2:$B$324,3,FALSE),"") | F35: 3329A00746 | H35: Agilent
A36: 30-70956507-5 | C36: ORG-E-007 | D36: 5973A | E36: =IFERROR(VLOOKUP(D36,'Resumen Módulos'!$A$2:$B$324,3,FALSE),"") | F36: US70820663 | H36: Agilent
A37: 30-53670643-3 | C37: GC 7890 | D37: 5975 (G3170A) | E37: =IFERROR(VLOOKUP(D37,'Resumen Módulos'!$A$2:$B$324,3,FALSE),"") | F37: US592013808 | H37: Agilent
A38: 30-71616293-8 | C38: GC MSD | D38: 5977 (G7037A) | E38: =IFERROR(VLOOKUP(D38,'Resumen Módulos'!$A$2:$B$324,3,FALSE),"") | F38: US1426K302 | H38: Agilent
A39: 33-53487696-9 | C39: ID64 | D39: 5977C | E39: =IFERROR(VLOOKUP(D39,'Resumen Módulos'!$A$2:$B$324,3,FALSE),"") | F39: US2323MA14 | G39: 10.2 | H39: Agilent
A40: 30-71691354-2 | C40: GC 7820 | D40: 5977E | E40: =IFERROR(VLOOKUP(D40,'Resumen Módulos'!$A$2:$B$324,3,FALSE),"") | F40: US14060205 | H40: Agilent
...

Sheet Resumen Módulos
A1: Nombre Módulo | B1: Categoria Modulo | C1: Categoría Genérica | D1: Marca
A2: MBL 2100 | B2: Microscopios | C2: Microscopio | D2: A.KRÜSS
A3: API 2000 | B3: Espectrometría de masas | C3: Espectrómetro de masas triple cuadrupolo (LC-MS/MS) | D3: AB Sciex
A4: MDS Sciex | B4: Espectrometría de masas | C4: Espectrómetro de masas | D4: AB Sciex
A5: 0001-6354 | B5: Interfaces y comunicación | C5: Interfaz / Comunicación | D5: Agilent
A6: 0001-6501 | B6: Interfaces y comunicación | C6: Interfaz / Comunicación | D6: Agilent
A7: 1046A | B7: Detectores HPLC | C7: Detector de fluorescencia (FLD) | D7: Agilent
A8: 18594A | B8: Inyectores / Automuestreadores GC | C8: Automuestreador de líquidos (GC) | D8: Agilent
A9: 18594B | B9: Inyectores / Automuestreadores GC | C9: Automuestreador de líquidos (GC) | D9: Agilent
A10: 18596B | B10: Accesorios de automuestreador | C10: Bandeja de muestras | D10: Agilent
A11: 18596C | B11: Accesorios de automuestreador | C11: Bandeja de muestras | D11: Agilent
A12: 35900E | B12: Interfaces y comunicación | C12: Interfaz / Comunicación | D12: Agilent
... A16: 5973A | B16: Detectores GC - MSD | C16: Detector selectivo de masas (MSD) | D16: Agilent
A17: 5975 | B17: Detectores GC - MSD | C17: Detector selectivo de masas (MSD) | D17: Agilent
A18: 5975 (G3170A) | B18: Detectores GC - MSD | C18: Detector selectivo de masas (MSD) | D18: Agilent
A19: 5977 (G7037A) | B19: Detectores GC - MSD | C19: Detector selectivo de masas (MSD) | D19: Agilent
A20: 5977C | B20: Detectores GC - MSD | C20: Detector selectivo de masas (MSD) | D20: Agilent
A21: 5977E | B21: Detectores GC - MSD | C21: Detector selectivo de masas (MSD) | D21: Agilent
A22: 59864B | B22: Válvulas | C22: Válvula selectora | D22: Agilent
A23: 7673A (18593A) | B23: Inyectores / Automuestreadores GC | C23: Automuestreador de líquidos (GC) | D23: Agilent
A24: 7673B (18593B) | B24: Inyectores / Automuestreadores GC | C24: Automuestreador de líquidos (GC) | D24: Agilent
A25: 7683 | B25: Inyectores / Automuestreadores GC | C25: Automuestreador de líquidos (GC) | D25: Agilent
A26: 7683 (G2613A) | B26: Automuestreadores (General) | C26: Automuestreador | D26: Agilent
A27: 7683B | B27: Inyector automático GC | C27: Automuestreador de líquidos (GC) | D27: Agilent
A28: 7693 (G4513A) | B28: Inyector automático GC | C28: Automuestreador de líquidos (GC) | D28: Agilent
A29: 7694 | B29: Muestreadores de headspace (GC) | C29: Muestreador de headspace | D29: Agilent
A30: 7694 (G1290B) | B30: Muestreadores de headspace (GC) | C30: Muestreador de headspace | D30: Agilent
A31: 7694E | B31: Muestreadores de headspace (GC) | C31: Muestreador de headspace | D31: Agilent
A32: 7694E (G1290A) | B32: Muestreadores de headspace (GC) | C32: Muestreador de headspace | D32: Agilent
A33: 7694E (G1883A) | B33: Muestreadores de headspace (GC) | C33: Muestreador de headspace | D33: Agilent
A34: 7697 | B34: Muestreadores de headspace (GC) | C34: Muestreador de headspace | D34: Agilent
A35: 79851AX | B35: Compartimento de columnas HPLC | C35: Compartimento de columnas (TCC) | D35: Agilent
A36: 79852A | B36: Detectores HPLC | C36: Detector UV de longitud de onda variable (VWD) | D36: Agilent
A37: 79852AX | B37: Detectores HPLC | C37: Detector UV de longitud de onda variable (VWD) | D37: Agilent
A38: 79853C | B38: Detectores HPLC | C38: Detector de arreglo de diodos (DAD) | D38: Agilent
A39: 79854A | B39: Bombas HPLC | C39: Bomba cuaternaria | D39: Agilent
A40: 79854C | B40: Bombas HPLC | C40: Bomba cuaternaria | D40: Agilent
A41: 79855A | B41: Inyectores / Automuestreadores HPLC | C41: Automuestreador (HPLC) | D41: Agilent
A42: 79856A | B42: Desgasificadores HPLC | C42: Desgasificador | D42: Agilent
A43: 79856BX | B43: Desgasificadores HPLC | C43: Desgasificador | D43: Agilent
...
