Workbook

Sheet Hoja1
A1: Nro. de Parte | B1: Descripción | C1: Posicion arancelaria | D1: Marca | E1: Origen
A2: Nro. de Parte | B2: Descripción | D2: Marca | E2: Origen
A3: µECD | B3: Detector | D3: Agilent
A4: 0,6528 | B4: PRESSURE REGULATOR | D4: FDGS
A5: 00000HHO | B5: Kromasil Guard Holder for 2.1-4.6mmID Cartridges | D5: ZZZ
A6: 00000KCO | B6: Guard Coupler 2.1-21.2mm | D6: ZZZ
A7: 0001-1019 | B7: 1100 Degasser Retrofit Kit | D7: BIO
A8: 0001-1020(US) | B8: 1100 Degasser Kit 480 uL | D8: BIO
A9: 0001-1020(US)-B | B9: 1100 Degasser Kit 480 uL | D9: BIO
A10: 0001-6354 | B10: Dg, 2003 Stand Alone, 4-chan, 480ul, w/validation | D10: BIO
A11: 0001-6501 | B11: Degasser | D11: ZZZ
A12: 0003-6353-A | B12: Degasi Plus Classic 3-ch | D12: BIO
A13: 00-1266 | B13: TUBE PTFE 1/4"OD 3/16"ID | D13: PEK
A14: 00-1291 | B14: TUBE PTFE 4MMOD 3MMID | D14: PEK
... A24: 00G-4375-E0 | B24: Synergi 4 µm Hydro-RP 80 Å, LC Column 250 x 4.6 mm | D24: ZZZ
A25: 0100-0073 | B25: Reducer 1/16"-1/18" SS | C25: 7412.20.00.290N | D25: Agilent
A26: 0100-0118 | B26: Swagelok to female NPT, 1/8-1/4in brass | D26: Agilent | E26: EEUU
A27: 0100-0118B | B27: Swagelok to female NPT, 1/8-1/4in brass | D27: Agilent
A28: 0100-0120 | B28: Reducer Union 1/4 - TBG 1/8 - T3G | D28: Agilent
A29: 0100-0121 | B29: 1/8 to 1/4 ss reducing nut | C29: 7307.29.00.100B | D29: Agilent
A30: 0100-0124 | B30: Union, 1/16in SS | D30: Agilent | E30: EEUU
A31: 0100-0549 | B31: Ring, Clamping | C31: 9027.90.99.900G | D31: Agilent
A32: 0100-0900 | B32: ZDV union, stainless steel, with fittings | D32: Agilent | E32: EEUU
A33: 0100-1145 | B33: Silver Plated | D33: Agilent
A34: 0100-1186 | B34: Ferrule vespel | D34: Agilent
A35: 0100-1324 | B35: Ferrule, 1/4 inch graphite, 10 pk. | D35: Agilent
A36: 0100-1329 | B36: Ferrule 1/16'' Vespel | D36: Agilent
A37: 0100-1332 | B37: Ferrule, 1/8in 85% Vespel 10/pk (equivalent to J&W | D37: Agilent
A38: 0100-1342 | B38: Ferrule, reducing 1/8-1/16 inch Vespel, 10/pk | D38: Agilent | E38: EEUU
A39: 0100-1342B | B39: 10% Vespel 1/8 to 1/16 reducing ferrule | D39: Agilent
A40: 0100-1372 | B40: Ferrule, 1/8in 60%Vespel, no hole 10/pk | D40: Agilent
A41: 0100-1395 | B41: KF 50 Clamp for Diff pump | D41: Agilent
A42: 0100-1398 | B42: KF 50 Clamp for GC Interfase and bottom of forelin | D42: Agilent
A43: 0100-13AGS | B43: KF 16 Blank Cap | D43: Agilent
A44: 0100-1426AGS | B44: KF 40 Top of foreline trap | D44: Agilent
A45: 0100-1512 | B45: Ferrule, polymide 1/16 in | D45: Agilent
A46: 0100-1513 | B46: Line mega Bore column | D46: Agilent
A47: 0100-1513B | B47: Line mega Bore column | D47: Agilent
A48: 0100-1514 | B48: Liner, 32mm column | D48: Agilent
A49: 0100-1515 | B49: Bulkhead Union, 1/16"-1/16" | D49: Agilent
...

Sheet Hoja2
A1: Marca | B1: Marca2 | C1: Cantidad
A2: {=_xlfn._xlws.SORT(_xlfn.UNIQUE(Hoja1!D3:D5068))} -> 0 | C2: =COUNTIF(Hoja1!C:C,A2) -> 0
A3: 2MA | C3: =COUNTIF(Hoja1!C:C,A3) -> 0
A4: Accumax | B4: Accumax | C4: =COUNTIF(Hoja1!C:C,A4) -> 0
A5: Agilent | B5: Agilent | C5: =COUNTIF(Hoja1!C:C,A5) -> 0
A6: AGS | C6: =COUNTIF(Hoja1!C:C,A6) -> 0
A7: AOT | C7: =COUNTIF(Hoja1!C:C,A7) -> 0
A8: ATL | C8: =COUNTIF(Hoja1!C:C,A8) -> 0
A9: BAN | C9: =COUNTIF(Hoja1!C:C,A9) -> 0
A10: BGB | C10: =COUNTIF(Hoja1!C:C,A10) -> 0
A11: BIK | C11: =COUNTIF(Hoja1!C:C,A11) -> 0
A12: BIO | C12: =COUNTIF(Hoja1!C:C,A12) -> 0
A13: BOE | C13: =COUNTIF(Hoja1!C:C,A13) -> 0
A14: CHR | C14: =COUNTIF(Hoja1!C:C,A14) -> 0
A15: CIC | C15: =COUNTIF(Hoja1!C:C,A15) -> 0
A16: CIT | C16: =COUNTIF(Hoja1!C:C,A16) -> 0
A17: CPL | C17: =COUNTIF(Hoja1!C:C,A17) -> 0
A18: CTC | B18: CTC | C18: =COUNTIF(Hoja1!C:C,A18) -> 0
A19: CTS | B19: CTS | C19: =COUNTIF(Hoja1!C:C,A19) -> 0
A20: Data Apex | B20: Data Apex | C20: =COUNTIF(Hoja1!C:C,A20) -> 0
A21: DEL | C21: =COUNTIF(Hoja1!C:C,A21) -> 0
A22: DON | C22: =COUNTIF(Hoja1!C:C,A22) -> 0
A23: EST | B23: EST | C23: =COUNTIF(Hoja1!C:C,A23) -> 0
A24: EVO | C24: =COUNTIF(Hoja1!C:C,A24) -> 0
A25: EWS | C25: =COUNTIF(Hoja1!C:C,A25) -> 0
A26: FDGS | B26: FDGS | C26: =COUNTIF(Hoja1!C:C,A26) -> 0
A27: FLE | C27: =COUNTIF(Hoja1!C:C,A27) -> 0
A28: Flusitec | B28: Flusitec | C28: =COUNTIF(Hoja1!C:C,A28) -> 0
A29: FUN | C29: =COUNTIF(Hoja1!C:C,A29) -> 0
A30: GJC | C30: =COUNTIF(Hoja1!C:C,A30) -> 0
A31: HAU | C31: =COUNTIF(Hoja1!C:C,A31) -> 0
A32: HML | C32: =COUNTIF(Hoja1!C:C,A32) -> 0
A33: HTA | B33: HTA | C33: =COUNTIF(Hoja1!C:C,A33) -> 0
A34: HYD | C34: =COUNTIF(Hoja1!C:C,A34) -> 0
A35: JAS | C35: =COUNTIF(Hoja1!C:C,A35) -> 0
A36: Knauer | B36: Knauer | C36: =COUNTIF(Hoja1!C:C,A36) -> 0
A37: Kruss | B37: Kruss | C37: =COUNTIF(Hoja1!C:C,A37) -> 0
A38: LAB | C38: =COUNTIF(Hoja1!C:C,A38) -> 0
A39: LEN | C39: =COUNTIF(Hoja1!C:C,A39) -> 0
A40: LOC | C40: =COUNTIF(Hoja1!C:C,A40) -> 0
...
